Workbook

Sheet נתוני אימונים
A1: 📊 ניתוח אימוני SUP — לוח מעקב
A2: תאריך | B2: סוג אימון | C2: מיקום | D2: מרחק (ק״מ) | E2: זמן | F2: מהירות (קמ״ש) | G2: דופק ממוצע | H2: SPM | I2: DPS (מ׳) | J2: זמן Z3 | K2: זמן Z4 | L2: זמן Z5
A3: 03.12.2025 | B3: ספרינטים | C3: ים | D3: 6.95 | E3: 1:21:09 | F3: 5.1 | G3: 142 | H3: 32 | I3: 2.79 | J3: 0:38:17 | K3: 0:32:00 | L3: 0:01:15
A4: 06.12.2025 | B4: טמפו | C4: ים | D4: 9.6 | E4: 1:13:53 | F4: 7.8 | G4: 146 | H4: 43 | I4: 3.01 | J4: 0:28:39 | K4: 0:41:27 | L4: 0:00
A5: 09.12.2025 | B5: טמפו | C5: נחל | D5: 10.36 | E5: 1:20:11 | F5: 7.8 | G5: 136 | H5: 41 | I5: 3.17 | J5: 0:40:31 | K5: 0:21:36 | L5: 0:00
A6: 12.12.2025 | B6: אירובי | C6: נחל | D6: 9.32 | E6: 1:18:11 | F6: 7.1 | G6: 129 | H6: 37 | I6: 3.29 | J6: 1:00:35 | K6: 0:00 | L6: 0:00
A7: 13.12.2025 | B7: ספרינטים | C7: ים | D7: 8.63 | E7: 1:15:35 | F7: 6.8 | G7: 133 | H7: 39 | I7: 2.96 | J7: 0:50:03 | K7: 0:08:19 | L7: 0:00
A8: 15.12.2025 | B8: טמפו | C8: ים | D8: 9.72 | E8: 1:20:01 | F8: 7.3 | G8: 139 | H8: 40 | I8: 3.03 | J8: 0:51:03 | K8: 0:17:29 | L8: 0:00
A9: 17.12.2025 | B9: אירובי | C9: נחל | D9: 9.98 | E9: 1:19:15 | F9: 7.6 | G9: 130 | H9: 39 | I9: 3.28 | J9: 1:01:50 | K9: 0:00 | L9: 0:00
A10: 19.12.2025 | B10: אירובי | C10: ים | D10: 9.75 | E10: 1:19:43 | F10: 7.3 | G10: 139 | H10: 41 | I10: 2.99 | J10: 0:59:12 | K10: 0:13:28 | L10: 0:00
A11: 20.12.2025 | B11: אירובי | C11: ים | D11: 9.14 | E11: 1:19:53 | F11: 6.9 | G11: 134 | H11: 41 | I11: 2.8 | J11: 0:43:26 | K11: 0:15:03 | L11: 0:00:26
A12: 22.12.2025 | B12: ספרינטים | C12: ים | D12: 8.01 | E12: 1:24:15 | F12: 5.7 | G12: 85 | H12: 34 | I12: 2.8 | J12: 0:00 | K12: 0:00 | L12: 0:00
A13: 26.12.2025 | B13: טמפו | C13: ים | D13: 9.23 | E13: 1:15:09 | F13: 7.4 | G13: 144 | H13: 40 | I13: 3.07 | J13: 0:27:52 | K13: 0:39:07 | L13: 0:00
A14: 27.12.2025 | B14: אירובי | C14: נחל | D14: 9.8 | E14: 1:17:27 | F14: 7.6 | G14: 134 | H14: 39 | I14: 3.26 | J14: 1:05:37 | K14: 0:00 | L14: 0:00
... A49: 06.06.2026 | B49: ספרינטים | C49: ים | D49: 6.61 | E49: 2:01:58 | F49: 3.3 | G49: 161 | H49: 44 | I49: 4.53 | J49: 1:08 | K49: 57:53 | L49: 59:20

Sheet סיכום חודשי
A1: 📅 SUP — סיכום חודשי לפי סוג אימון 📋
A2: חודש | B2: סוג אימון | C2: אימונים | D2: מהירות ממוצע | E2: דופק ממוצע | F2: DPS ממוצע | G2: מרחק כולל
A3: דצמבר 2025 | B3: אירובי | C3: =IFERROR(COUNTIFS('נתוני אימונים'!A:A,"*.12.2025*",'נתוני אימונים'!B:B,"אירובי"),0) | D3: =IFERROR(AVERAGEIFS('נתוני אימונים'!F:F,'נתוני אימונים'!A:A,"*.12.2025*",'נתוני אימונים'!B:B,"אירובי"),"") | E3: =IFERROR(AVERAGEIFS('נתוני אימונים'!G:G,'נתוני אימונים'!A:A,"*.12.2025*",'נתוני אימונים'!B:B,"אירובי"),"") | F3: =IFERROR(AVERAGEIFS('נתוני אימונים'!I:I,'נתוני אימונים'!A:A,"*.12.2025*",'נתוני אימונים'!B:B,"אירובי"),"") | G3: =IFERROR(SUMIFS('נתוני אימונים'!D:D,'נתוני אימונים'!A:A,"*.12.2025*",'נתוני אימונים'!B:B,"אירובי"),"")
A4: דצמבר 2025 | B4: אירובי ארוך | C4: =IFERROR(COUNTIFS('נתוני אימונים'!A:A,"*.12.2025*",'נתוני אימונים'!B:B,"אירובי ארוך"),0) | D4: =IFERROR(AVERAGEIFS('נתוני אימונים'!F:F,'נתוני אימונים'!A:A,"*.12.2025*",'נתוני אימונים'!B:B,"אירובי ארוך"),"") | E4: =IFERROR(AVERAGEIFS('נתוני אימונים'!G:G,'נתוני אימונים'!A:A,"*.12.2025*",'נתוני אימונים'!B:B,"אירובי ארוך"),"") | F4: =IFERROR(AVERAGEIFS('נתוני אימונים'!I:I,'נתוני אימונים'!A:A,"*.12.2025*",'נתוני אימונים'!B:B,"אירובי ארוך"),"") | G4: =IFERROR(SUMIFS('נתוני אימונים'!D:D,'נתוני אימונים'!A:A,"*.12.2025*",'נתוני אימונים'!B:B,"אירובי ארוך"),"")
A5: דצמבר 2025 | B5: טמפו | C5: =IFERROR(COUNTIFS('נתוני אימונים'!A:A,"*.12.2025*",'נתוני אימונים'!B:B,"טמפו"),0) | D5: =IFERROR(AVERAGEIFS('נתוני אימונים'!F:F,'נתוני אימונים'!A:A,"*.12.2025*",'נתוני אימונים'!B:B,"טמפו"),"") | E5: =IFERROR(AVERAGEIFS('נתוני אימונים'!G:G,'נתוני אימונים'!A:A,"*.12.2025*",'נתוני אימונים'!B:B,"טמפו"),"") | F5: =IFERROR(AVERAGEIFS('נתוני אימונים'!I:I,'נתוני אימונים'!A:A,"*.12.2025*",'נתוני אימונים'!B:B,"טמפו"),"") | G5: =IFERROR(SUMIFS('נתוני אימונים'!D:D,'נתוני אימונים'!A:A,"*.12.2025*",'נתוני אימונים'!B:B,"טמפו"),"")
A6: דצמבר 2025 | B6: ספרינטים | C6: =IFERROR(COUNTIFS('נתוני אימונים'!A:A,"*.12.2025*",'נתוני אימונים'!B:B,"ספרינטים"),0) | D6: =IFERROR(AVERAGEIFS('נתוני אימונים'!F:F,'נתוני אימונים'!A:A,"*.12.2025*",'נתוני אימונים'!B:B,"ספרינטים"),"") | E6: =IFERROR(AVERAGEIFS('נתוני אימונים'!G:G,'נתוני אימונים'!A:A,"*.12.2025*",'נתוני אימונים'!B:B,"ספרינטים"),"") | F6: =IFERROR(AVERAGEIFS('נתוני אימונים'!I:I,'נתוני אימונים'!A:A,"*.12.2025*",'נתוני אימונים'!B:B,"ספרינטים"),"") | G6: =IFERROR(SUMIFS('נתוני אימונים'!D:D,'נתוני אימונים'!A:A,"*.12.2025*",'נתוני אימונים'!B:B,"ספרינטים"),"")
A7: דצמבר 2025 | B7: סה״כ חודש | C7: =IFERROR(COUNTIFS('נתוני אימונים'!A:A,"*.12.2025*"),0) | D7: =IFERROR(AVERAGEIFS('נתוני אימונים'!F:F,'נתוני אימונים'!A:A,"*.12.2025*"),"") | E7: =IFERROR(AVERAGEIFS('נתוני אימונים'!G:G,'נתוני אימונים'!A:A,"*.12.2025*"),"") | F7: =IFERROR(AVERAGEIFS('נתוני אימונים'!I:I,'נתוני אימונים'!A:A,"*.12.2025*"),"") | G7: =IFERROR(SUMIFS('נתוני אימונים'!D:D,'נתוני אימונים'!A:A,"*.12.2025*"),"")
A10: ינואר 2026 | B10: אירובי | C10: =IFERROR(COUNTIFS('נתוני אימונים'!A:A,"*.01.2026*",'נתוני אימונים'!B:B,"אירובי"),0) | D10: =IFERROR(AVERAGEIFS('נתוני אימונים'!F:F,'נתוני אימונים'!A:A,"*.01.2026*",'נתוני אימונים'!B:B,"אירובי"),"") | E10: =IFERROR(AVERAGEIFS('נתוני אימונים'!G:G,'נתוני אימונים'!A:A,"*.01.2026*",'נתוני אימונים'!B:B,"אירובי"),"") | F10: =IFERROR(AVERAGEIFS('נתוני אימונים'!I:I,'נתוני אימונים'!A:A,"*.01.2026*",'נתוני אימונים'!B:B,"אירובי"),"") | G10: =IFERROR(SUMIFS('נתוני אימונים'!D:D,'נתוני אימונים'!A:A,"*.01.2026*",'נתוני אימונים'!B:B,"אירובי"),"")
A11: ינואר 2026 | B11: אירובי ארוך | C11: =IFERROR(COUNTIFS('נתוני אימונים'!A:A,"*.01.2026*",'נתוני אימונים'!B:B,"אירובי ארוך"),0) | D11: =IFERROR(AVERAGEIFS('נתוני אימונים'!F:F,'נתוני אימונים'!A:A,"*.01.2026*",'נתוני אימונים'!B:B,"אירובי ארוך"),"") | E11: =IFERROR(AVERAGEIFS('נתוני אימונים'!G:G,'נתוני אימונים'!A:A,"*.01.2026*",'נתוני אימונים'!B:B,"אירובי ארוך"),"") | F11: =IFERROR(AVERAGEIFS('נתוני אימונים'!I:I,'נתוני אימונים'!A:A,"*.01.2026*",'נתוני אימונים'!B:B,"אירובי ארוך"),"") | G11: =IFERROR(SUMIFS('נתוני אימונים'!D:D,'נתוני אימונים'!A:A,"*.01.2026*",'נתוני אימונים'!B:B,"אירובי ארוך"),"")
A12: ינואר 2026 | B12: טמפו | C12: =IFERROR(COUNTIFS('נתוני אימונים'!A:A,"*.01.2026*",'נתוני אימונים'!B:B,"טמפו"),0) | D12: =IFERROR(AVERAGEIFS('נתוני אימונים'!F:F,'נתוני אימונים'!A:A,"*.01.2026*",'נתוני אימונים'!B:B,"טמפו"),"") | E12: =IFERROR(AVERAGEIFS('נתוני אימונים'!G:G,'נתוני אימונים'!A:A,"*.01.2026*",'נתוני אימונים'!B:B,"טמפו"),"") | F12: =IFERROR(AVERAGEIFS('נתוני אימונים'!I:I,'נתוני אימונים'!A:A,"*.01.2026*",'נתוני אימונים'!B:B,"טמפו"),"") | G12: =IFERROR(SUMIFS('נתוני אימונים'!D:D,'נתוני אימונים'!A:A,"*.01.2026*",'נתוני אימונים'!B:B,"טמפו"),"")
A13: ינואר 2026 | B13: ספרינטים | C13: =IFERROR(COUNTIFS('נתוני אימונים'!A:A,"*.01.2026*",'נתוני אימונים'!B:B,"ספרינטים"),0) | D13: =IFERROR(AVERAGEIFS('נתוני אימונים'!F:F,'נתוני אימונים'!A:A,"*.01.2026*",'נתוני אימונים'!B:B,"ספרינטים"),"") | E13: =IFERROR(AVERAGEIFS('נתוני אימונים'!G:G,'נתוני אימונים'!A:A,"*.01.2026*",'נתוני אימונים'!B:B,"ספרינטים"),"") | F13: =IFERROR(AVERAGEIFS('נתוני אימונים'!I:I,'נתוני אימונים'!A:A,"*.01.2026*",'נתוני אימונים'!B:B,"ספרינטים"),"") | G13: =IFERROR(SUMIFS('נתוני אימונים'!D:D,'נתוני אימונים'!A:A,"*.01.2026*",'נתוני אימונים'!B:B,"ספרינטים"),"")
A14: ינואר 2026 | B14: סה״כ חודש | C14: =IFERROR(COUNTIFS('נתוני אימונים'!A:A,"*.01.2026*"),0) | D14: =IFERROR(AVERAGEIFS('נתוני אימונים'!F:F,'נתוני אימונים'!A:A,"*.01.2026*"),"") | E14: =IFERROR(AVERAGEIFS('נתוני אימונים'!G:G,'נתוני אימונים'!A:A,"*.01.2026*"),"") | F14: =IFERROR(AVERAGEIFS('נתוני אימונים'!I:I,'נתוני אימונים'!A:A,"*.01.2026*"),"") | G14: =IFERROR(SUMIFS('נתוני אימונים'!D:D,'נתוני אימונים'!A:A,"*.01.2026*"),"")
A17: פברואר 2026 | B17: אירובי | C17: =IFERROR(COUNTIFS('נתוני אימונים'!A:A,"*.02.2026*",'נתוני אימונים'!B:B,"אירובי"),0) | D17: =IFERROR(AVERAGEIFS('נתוני אימונים'!F:F,'נתוני אימונים'!A:A,"*.02.2026*",'נתוני אימונים'!B:B,"אירובי"),"") | E17: =IFERROR(AVERAGEIFS('נתוני אימונים'!G:G,'נתוני אימונים'!A:A,"*.02.2026*",'נתוני אימונים'!B:B,"אירובי"),"") | F17: =IFERROR(AVERAGEIFS('נתוני אימונים'!I:I,'נתוני אימונים'!A:A,"*.02.2026*",'נתוני אימונים'!B:B,"אירובי"),"") | G17: =IFERROR(SUMIFS('נתוני אימונים'!D:D,'נתוני אימונים'!A:A,"*.02.2026*",'נתוני אימונים'!B:B,"אירובי"),"")
A18: פברואר 2026 | B18: אירובי ארוך | C18: =IFERROR(COUNTIFS('נתוני אימונים'!A:A,"*.02.2026*",'נתוני אימונים'!B:B,"אירובי ארוך"),0) | D18: =IFERROR(AVERAGEIFS('נתוני אימונים'!F:F,'נתוני אימונים'!A:A,"*.02.2026*",'נתוני אימונים'!B:B,"אירובי ארוך"),"") | E18: =IFERROR(AVERAGEIFS('נתוני אימונים'!G:G,'נתוני אימונים'!A:A,"*.02.2026*",'נתוני אימונים'!B:B,"אירובי ארוך"),"") | F18: =IFERROR(AVERAGEIFS('נתוני אימונים'!I:I,'נתוני אימונים'!A:A,"*.02.2026*",'נתוני אימונים'!B:B,"אירובי ארוך"),"") | G18: =IFERROR(SUMIFS('נתוני אימונים'!D:D,'נתוני אימונים'!A:A,"*.02.2026*",'נתוני אימונים'!B:B,"אירובי ארוך"),"")
A19: פברואר 2026 | B19: טמפו | C19: =IFERROR(COUNTIFS('נתוני אימונים'!A:A,"*.02.2026*",'נתוני אימונים'!B:B,"טמפו"),0) | D19: =IFERROR(AVERAGEIFS('נתוני אימונים'!F:F,'נתוני אימונים'!A:A,"*.02.2026*",'נתוני אימונים'!B:B,"טמפו"),"") | E19: =IFERROR(AVERAGEIFS('נתוני אימונים'!G:G,'נתוני אימונים'!A:A,"*.02.2026*",'נתוני אימונים'!B:B,"טמפו"),"") | F19: =IFERROR(AVERAGEIFS('נתוני אימונים'!I:I,'נתוני אימונים'!A:A,"*.02.2026*",'נתוני אימונים'!B:B,"טמפו"),"") | G19: =IFERROR(SUMIFS('נתוני אימונים'!D:D,'נתוני אימונים'!A:A,"*.02.2026*",'נתוני אימונים'!B:B,"טמפו"),"")
A20: פברואר 2026 | B20: ספרינטים | C20: =IFERROR(COUNTIFS('נתוני אימונים'!A:A,"*.02.2026*",'נתוני אימונים'!B:B,"ספרינטים"),0) | D20: =IFERROR(AVERAGEIFS('נתוני אימונים'!F:F,'נתוני אימונים'!A:A,"*.02.2026*",'נתוני אימונים'!B:B,"ספרינטים"),"") | E20: =IFERROR(AVERAGEIFS('נתוני אימונים'!G:G,'נתוני אימונים'!A:A,"*.02.2026*",'נתוני אימונים'!B:B,"ספרינטים"),"") | F20: =IFERROR(AVERAGEIFS('נתוני אימונים'!I:I,'נתוני אימונים'!A:A,"*.02.2026*",'נתוני אימונים'!B:B,"ספרינטים"),"") | G20: =IFERROR(SUMIFS('נתוני אימונים'!D:D,'נתוני אימונים'!A:A,"*.02.2026*",'נתוני אימונים'!B:B,"ספרינטים"),"")
A21: פברואר 2026 | B21: סה״כ חודש | C21: =IFERROR(COUNTIFS('נתוני אימונים'!A:A,"*.02.2026*"),0) | D21: =IFERROR(AVERAGEIFS('נתוני אימונים'!F:F,'נתוני אימונים'!A:A,"*.02.2026*"),"") | E21: =IFERROR(AVERAGEIFS('נתוני אימונים'!G:G,'נתוני אימונים'!A:A,"*.02.2026*"),"") | F21: =IFERROR(AVERAGEIFS('נתוני אימונים'!I:I,'נתוני אימונים'!A:A,"*.02.2026*"),"") | G21: =IFERROR(SUMIFS('נתוני אימונים'!D:D,'נתוני אימונים'!A:A,"*.02.2026*"),"")
A24: מרץ 2026 | B24: אירובי | C24: =IFERROR(COUNTIFS('נתוני אימונים'!A:A,"*.03.2026*",'נתוני אימונים'!B:B,"אירובי"),0) | D24: =IFERROR(AVERAGEIFS('נתוני אימונים'!F:F,'נתוני אימונים'!A:A,"*.03.2026*",'נתוני אימונים'!B:B,"אירובי"),"") | E24: =IFERROR(AVERAGEIFS('נתוני אימונים'!G:G,'נתוני אימונים'!A:A,"*.03.2026*",'נתוני אימונים'!B:B,"אירובי"),"") | F24: =IFERROR(AVERAGEIFS('נתוני אימונים'!I:I,'נתוני אימונים'!A:A,"*.03.2026*",'נתוני אימונים'!B:B,"אירובי"),"") | G24: =IFERROR(SUMIFS('נתוני אימונים'!D:D,'נתוני אימונים'!A:A,"*.03.2026*",'נתוני אימונים'!B:B,"אירובי"),"")
A25: מרץ 2026 | B25: אירובי ארוך | C25: =IFERROR(COUNTIFS('נתוני אימונים'!A:A,"*.03.2026*",'נתוני אימונים'!B:B,"אירובי ארוך"),0) | D25: =IFERROR(AVERAGEIFS('נתוני אימונים'!F:F,'נתוני אימונים'!A:A,"*.03.2026*",'נתוני אימונים'!B:B,"אירובי ארוך"),"") | E25: =IFERROR(AVERAGEIFS('נתוני אימונים'!G:G,'נתוני אימונים'!A:A,"*.03.2026*",'נתוני אימונים'!B:B,"אירובי ארוך"),"") | F25: =IFERROR(AVERAGEIFS('נתוני אימונים'!I:I,'נתוני אימונים'!A:A,"*.03.2026*",'נתוני אימונים'!B:B,"אירובי ארוך"),"") | G25: =IFERROR(SUMIFS('נתוני אימונים'!D:D,'נתוני אימונים'!A:A,"*.03.2026*",'נתוני אימונים'!B:B,"אירובי ארוך"),"")
A26: מרץ 2026 | B26: טמפו | C26: =IFERROR(COUNTIFS('נתוני אימונים'!A:A,"*.03.2026*",'נתוני אימונים'!B:B,"טמפו"),0) | D26: =IFERROR(AVERAGEIFS('נתוני אימונים'!F:F,'נתוני אימונים'!A:A,"*.03.2026*",'נתוני אימונים'!B:B,"טמפו"),"") | E26: =IFERROR(AVERAGEIFS('נתוני אימונים'!G:G,'נתוני אימונים'!A:A,"*.03.2026*",'נתוני אימונים'!B:B,"טמפו"),"") | F26: =IFERROR(AVERAGEIFS('נתוני אימונים'!I:I,'נתוני אימונים'!A:A,"*.03.2026*",'נתוני אימונים'!B:B,"טמפו"),"") | G26: =IFERROR(SUMIFS('נתוני אימונים'!D:D,'נתוני אימונים'!A:A,"*.03.2026*",'נתוני אימונים'!B:B,"טמפו"),"")
A27: מרץ 2026 | B27: ספרינטים | C27: =IFERROR(COUNTIFS('נתוני אימונים'!A:A,"*.03.2026*",'נתוני אימונים'!B:B,"ספרינטים"),0) | D27: =IFERROR(AVERAGEIFS('נתוני אימונים'!F:F,'נתוני אימונים'!A:A,"*.03.2026*",'נתוני אימונים'!B:B,"ספרינטים"),"") | E27: =IFERROR(AVERAGEIFS('נתוני אימונים'!G:G,'נתוני אימונים'!A:A,"*.03.2026*",'נתוני אימונים'!B:B,"ספרינטים"),"") | F27: =IFERROR(AVERAGEIFS('נתוני אימונים'!I:I,'נתוני אימונים'!A:A,"*.03.2026*",'נתוני אימונים'!B:B,"ספרינטים"),"") | G27: =IFERROR(SUMIFS('נתוני אימונים'!D:D,'נתוני אימונים'!A:A,"*.03.2026*",'נתוני אימונים'!B:B,"ספרינטים"),"")
A28: מרץ 2026 | B28: סה״כ חודש | C28: =IFERROR(COUNTIFS('נתוני אימונים'!A:A,"*.03.2026*"),0) | D28: =IFERROR(AVERAGEIFS('נתוני אימונים'!F:F,'נתוני אימונים'!A:A,"*.03.2026*"),"") | E28: =IFERROR(AVERAGEIFS('נתוני אימונים'!G:G,'נתוני אימונים'!A:A,"*.03.2026*"),"") | F28: =IFERROR(AVERAGEIFS('נתוני אימונים'!I:I,'נתוני אימונים'!A:A,"*.03.2026*"),"") | G28: =IFERROR(SUMIFS('נתוני אימונים'!D:D,'נתוני אימונים'!A:A,"*.03.2026*"),"")
A31: אפריל 2026 | B31: אירובי | C31: =IFERROR(COUNTIFS('נתוני אימונים'!A:A,"*.04.2026*",'נתוני אימונים'!B:B,"אירובי"),0) | D31: =IFERROR(AVERAGEIFS('נתוני אימונים'!F:F,'נתוני אימונים'!A:A,"*.04.2026*",'נתוני אימונים'!B:B,"אירובי"),"") | E31: =IFERROR(AVERAGEIFS('נתוני אימונים'!G:G,'נתוני אימונים'!A:A,"*.04.2026*",'נתוני אימונים'!B:B,"אירובי"),"") | F31: =IFERROR(AVERAGEIFS('נתוני אימונים'!I:I,'נתוני אימונים'!A:A,"*.04.2026*",'נתוני אימונים'!B:B,"אירובי"),"") | G31: =IFERROR(SUMIFS('נתוני אימונים'!D:D,'נתוני אימונים'!A:A,"*.04.2026*",'נתוני אימונים'!B:B,"אירובי"),"")
A32: אפריל 2026 | B32: אירובי ארוך | C32: =IFERROR(COUNTIFS('נתוני אימונים'!A:A,"*.04.2026*",'נתוני אימונים'!B:B,"אירובי ארוך"),0) | D32: =IFERROR(AVERAGEIFS('נתוני אימונים'!F:F,'נתוני אימונים'!A:A,"*.04.2026*",'נתוני אימונים'!B:B,"אירובי ארוך"),"") | E32: =IFERROR(AVERAGEIFS('נתוני אימונים'!G:G,'נתוני אימונים'!A:A,"*.04.2026*",'נתוני אימונים'!B:B,"אירובי ארוך"),"") | F32: =IFERROR(AVERAGEIFS('נתוני אימונים'!I:I,'נתוני אימונים'!A:A,"*.04.2026*",'נתוני אימונים'!B:B,"אירובי ארוך"),"") | G32: =IFERROR(SUMIFS('נתוני אימונים'!D:D,'נתוני אימונים'!A:A,"*.04.2026*",'נתוני אימונים'!B:B,"אירובי ארוך"),"")
A33: אפריל 2026 | B33: טמפו | C33: =IFERROR(COUNTIFS('נתוני אימונים'!A:A,"*.04.2026*",'נתוני אימונים'!B:B,"טמפו"),0) | D33: =IFERROR(AVERAGEIFS('נתוני אימונים'!F:F,'נתוני אימונים'!A:A,"*.04.2026*",'נתוני אימונים'!B:B,"טמפו"),"") | E33: =IFERROR(AVERAGEIFS('נתוני אימונים'!G:G,'נתוני אימונים'!A:A,"*.04.2026*",'נתוני אימונים'!B:B,"טמפו"),"") | F33: =IFERROR(AVERAGEIFS('נתוני אימונים'!I:I,'נתוני אימונים'!A:A,"*.04.2026*",'נתוני אימונים'!B:B,"טמפו"),"") | G33: =IFERROR(SUMIFS('נתוני אימונים'!D:D,'נתוני אימונים'!A:A,"*.04.2026*",'נתוני אימונים'!B:B,"טמפו"),"")
A34: אפריל 2026 | B34: ספרינטים | C34: =IFERROR(COUNTIFS('נתוני אימונים'!A:A,"*.04.2026*",'נתוני אימונים'!B:B,"ספרינטים"),0) | D34: =IFERROR(AVERAGEIFS('נתוני אימונים'!F:F,'נתוני אימונים'!A:A,"*.04.2026*",'נתוני אימונים'!B:B,"ספרינטים"),"") | E34: =IFERROR(AVERAGEIFS('נתוני אימונים'!G:G,'נתוני אימונים'!A:A,"*.04.2026*",'נתוני אימונים'!B:B,"ספרינטים"),"") | F34: =IFERROR(AVERAGEIFS('נתוני אימונים'!I:I,'נתוני אימונים'!A:A,"*.04.2026*",'נתוני אימונים'!B:B,"ספרינטים"),"") | G34: =IFERROR(SUMIFS('נתוני אימונים'!D:D,'נתוני אימונים'!A:A,"*.04.2026*",'נתוני אימונים'!B:B,"ספרינטים"),"")
A35: אפריל 2026 | B35: סה״כ חודש | C35: =IFERROR(COUNTIFS('נתוני אימונים'!A:A,"*.04.2026*"),0) | D35: =IFERROR(AVERAGEIFS('נתוני אימונים'!F:F,'נתוני אימונים'!A:A,"*.04.2026*"),"") | E35: =IFERROR(AVERAGEIFS('נתוני אימונים'!G:G,'נתוני אימונים'!A:A,"*.04.2026*"),"") | F35: =IFERROR(AVERAGEIFS('נתוני אימונים'!I:I,'נתוני אימונים'!A:A,"*.04.2026*"),"") | G35: =IFERROR(SUMIFS('נתוני אימונים'!D:D,'נתוני אימונים'!A:A,"*.04.2026*"),"")
A41: מאי 2026 | B41: אירובי | C41: =IFERROR(COUNTIFS('נתוני אימונים'!A:A,"*.05.2026*",'נתוני אימונים'!B:B,"אירובי"),0) | D41: =IFERROR(AVERAGEIFS('נתוני אימונים'!F:F,'נתוני אימונים'!A:A,"*.05.2026*",'נתוני אימונים'!B:B,"אירובי"),"") | E41: =IFERROR(AVERAGEIFS('נתוני אימונים'!G:G,'נתוני אימונים'!A:A,"*.05.2026*",'נתוני אימונים'!B:B,"אירובי"),"") | F41: =IFERROR(AVERAGEIFS('נתוני אימונים'!I:I,'נתוני אימונים'!A:A,"*.05.2026*",'נתוני אימונים'!B:B,"אירובי"),"") | G41: =IFERROR(SUMIFS('נתוני אימונים'!D:D,'נתוני אימונים'!A:A,"*.05.2026*",'נתוני אימונים'!B:B,"אירובי"),"")
A42: מאי 2026 | B42: אירובי ארוך | C42: =IFERROR(COUNTIFS('נתוני אימונים'!A:A,"*.05.2026*",'נתוני אימונים'!B:B,"אירובי ארוך"),0) | D42: =IFERROR(AVERAGEIFS('נתוני אימונים'!F:F,'נתוני אימונים'!A:A,"*.05.2026*",'נתוני אימונים'!B:B,"אירובי ארוך"),"") | E42: =IFERROR(AVERAGEIFS('נתוני אימונים'!G:G,'נתוני אימונים'!A:A,"*.05.2026*",'נתוני אימונים'!B:B,"אירובי ארוך"),"") | F42: =IFERROR(AVERAGEIFS('נתוני אימונים'!I:I,'נתוני אימונים'!A:A,"*.05.2026*",'נתוני אימונים'!B:B,"אירובי ארוך"),"") | G42: =IFERROR(SUMIFS('נתוני אימונים'!D:D,'נתוני אימונים'!A:A,"*.05.2026*",'נתוני אימונים'!B:B,"אירובי ארוך"),"")
A43: מאי 2026 | B43: טמפו | C43: =IFERROR(COUNTIFS('נתוני אימונים'!A:A,"*.05.2026*",'נתוני אימונים'!B:B,"טמפו"),0) | D43: =IFERROR(AVERAGEIFS('נתוני אימונים'!F:F,'נתוני אימונים'!A:A,"*.05.2026*",'נתוני אימונים'!B:B,"טמפו"),"") | E43: =IFERROR(AVERAGEIFS('נתוני אימונים'!G:G,'נתוני אימונים'!A:A,"*.05.2026*",'נתוני אימונים'!B:B,"טמפו"),"") | F43: =IFERROR(AVERAGEIFS('נתוני אימונים'!I:I,'נתוני אימונים'!A:A,"*.05.2026*",'נתוני אימונים'!B:B,"טמפו"),"") | G43: =IFERROR(SUMIFS('נתוני אימונים'!D:D,'נתוני אימונים'!A:A,"*.05.2026*",'נתוני אימונים'!B:B,"טמפו"),"")
A44: מאי 2026 | B44: ספרינטים | C44: =IFERROR(COUNTIFS('נתוני אימונים'!A:A,"*.05.2026*",'נתוני אימונים'!B:B,"ספרינטים"),0) | D44: =IFERROR(AVERAGEIFS('נתוני אימונים'!F:F,'נתוני אימונים'!A:A,"*.05.2026*",'נתוני אימונים'!B:B,"ספרינטים"),"") | E44: =IFERROR(AVERAGEIFS('נתוני אימונים'!G:G,'נתוני אימונים'!A:A,"*.05.2026*",'נתוני אימונים'!B:B,"ספרינטים"),"") | F44: =IFERROR(AVERAGEIFS('נתוני אימונים'!I:I,'נתוני אימונים'!A:A,"*.05.2026*",'נתוני אימונים'!B:B,"ספרינטים"),"") | G44: =IFERROR(SUMIFS('נתוני אימונים'!D:D,'נתוני אימונים'!A:A,"*.05.2026*",'נתוני אימונים'!B:B,"ספרינטים"),"")
A45: מאי 2026 | B45: סה"כ חודש | C45: =IFERROR(COUNTIFS('נתוני אימונים'!A:A,"*.05.2026*"),0) | D45: =IFERROR(AVERAGEIFS('נתוני אימונים'!F:F,'נתוני אימונים'!A:A,"*.05.2026*"),"") | E45: =IFERROR(AVERAGEIFS('נתוני אימונים'!G:G,'נתוני אימונים'!A:A,"*.05.2026*"),"") | F45: =IFERROR(AVERAGEIFS('נתוני אימונים'!I:I,'נתוני אימונים'!A:A,"*.05.2026*"),"") | G45: =IFERROR(SUMIFS('נתוני אימונים'!D:D,'נתוני אימונים'!A:A,"*.05.2026*"),"")
A48: יוני 2026 | B48: אירובי | C48: =IFERROR(COUNTIFS('נתוני אימונים'!A:A,"*.06.2026*",'נתוני אימונים'!B:B,"אירובי"),0) | D48: =IFERROR(AVERAGEIFS('נתוני אימונים'!F:F,'נתוני אימונים'!A:A,"*.06.2026*",'נתוני אימונים'!B:B,"אירובי"),"") | E48: =IFERROR(AVERAGEIFS('נתוני אימונים'!G:G,'נתוני אימונים'!A:A,"*.06.2026*",'נתוני אימונים'!B:B,"אירובי"),"") | F48: =IFERROR(AVERAGEIFS('נתוני אימונים'!I:I,'נתוני אימונים'!A:A,"*.06.2026*",'נתוני אימונים'!B:B,"אירובי"),"") | G48: =IFERROR(SUMIFS('נתוני אימונים'!D:D,'נתוני אימונים'!A:A,"*.06.2026*",'נתוני אימונים'!B:B,"אירובי"),"")
A49: יוני 2026 | B49: אירובי ארוך | C49: =IFERROR(COUNTIFS('נתוני אימונים'!A:A,"*.06.2026*",'נתוני אימונים'!B:B,"אירובי ארוך"),0) | D49: =IFERROR(AVERAGEIFS('נתוני אימונים'!F:F,'נתוני אימונים'!A:A,"*.06.2026*",'נתוני אימונים'!B:B,"אירובי ארוך"),"") | E49: =IFERROR(AVERAGEIFS('נתוני אימונים'!G:G,'נתוני אימונים'!A:A,"*.06.2026*",'נתוני אימונים'!B:B,"אירובי ארוך"),"") | F49: =IFERROR(AVERAGEIFS('נתוני אימונים'!I:I,'נתוני אימונים'!A:A,"*.06.2026*",'נתוני אימונים'!B:B,"אירובי ארוך"),"") | G49: =IFERROR(SUMIFS('נתוני אימונים'!D:D,'נתוני אימונים'!A:A,"*.06.2026*",'נתוני אימונים'!B:B,"אירובי ארוך"),"")
A50: יוני 2026 | B50: טמפו | C50: =IFERROR(COUNTIFS('נתוני אימונים'!A:A,"*.06.2026*",'נתוני אימונים'!B:B,"טמפו"),0) | D50: =IFERROR(AVERAGEIFS('נתוני אימונים'!F:F,'נתוני אימונים'!A:A,"*.06.2026*",'נתוני אימונים'!B:B,"טמפו"),"") | E50: =IFERROR(AVERAGEIFS('נתוני אימונים'!G:G,'נתוני אימונים'!A:A,"*.06.2026*",'נתוני אימונים'!B:B,"טמפו"),"") | F50: =IFERROR(AVERAGEIFS('נתוני אימונים'!I:I,'נתוני אימונים'!A:A,"*.06.2026*",'נתוני אימונים'!B:B,"טמפו"),"") | G50: =IFERROR(SUMIFS('נתוני אימונים'!D:D,'נתוני אימונים'!A:A,"*.06.2026*",'נתוני אימונים'!B:B,"טמפו"),"")
A51: יוני 2026 | B51: ספרינטים | C51: =IFERROR(COUNTIFS('נתוני אימונים'!A:A,"*.06.2026*",'נתוני אימונים'!B:B,"ספרינטים"),0) | D51: =IFERROR(AVERAGEIFS('נתוני אימונים'!F:F,'נתוני אימונים'!A:A,"*.06.2026*",'נתוני אימונים'!B:B,"ספרינטים"),"") | E51: =IFERROR(AVERAGEIFS('נתוני אימונים'!G:G,'נתוני אימונים'!A:A,"*.06.2026*",'נתוני אימונים'!B:B,"ספרינטים"),"") | F51: =IFERROR(AVERAGEIFS('נתוני אימונים'!I:I,'נתוני אימונים'!A:A,"*.06.2026*",'נתוני אימונים'!B:B,"ספרינטים"),"") | G51: =IFERROR(SUMIFS('נתוני אימונים'!D:D,'נתוני אימונים'!A:A,"*.06.2026*",'נתוני אימונים'!B:B,"ספרינטים"),"")
A52: יוני 2026 | B52: סה"כ חודש | C52: =IFERROR(COUNTIFS('נתוני אימונים'!A:A,"*.06.2026*"),0) | D52: =IFERROR(AVERAGEIFS('נתוני אימונים'!F:F,'נתוני אימונים'!A:A,"*.06.2026*"),"") | E52: =IFERROR(AVERAGEIFS('נתוני אימונים'!G:G,'נתוני אימונים'!A:A,"*.06.2026*"),"") | F52: =IFERROR(AVERAGEIFS('נתוני אימונים'!I:I,'נתוני אימונים'!A:A,"*.06.2026*"),"") | G52: =IFERROR(SUMIFS('נתוני אימונים'!D:D,'נתוני אימונים'!A:A,"*.06.2026*"),"")
A53: 🏆 סיכום כולל — כל האימונים
A54: סוג אימון | B54: סה״כ אימונים | C54: מהירות ממוצע | D54: דופק ממוצע | E54: DPS ממוצע | F54: סה״כ ק״מ | G54: % מסך האימונים
A55: אירובי | B55: =IFERROR(COUNTIF('נתוני אימונים'!B:B,"אירובי"),0) | C55: =IFERROR(AVERAGEIF('נתוני אימונים'!B:B,"אירובי",'נתוני אימונים'!F:F),"") | D55: =IFERROR(AVERAGEIF('נתוני אימונים'!B:B,"אירובי",'נתוני אימונים'!G:G),"") | E55: =IFERROR(AVERAGEIF('נתוני אימונים'!B:B,"אירובי",'נתוני אימונים'!I:I),"") | F55: =IFERROR(SUMIF('נתוני אימונים'!B:B,"אירובי",'נתוני אימונים'!D:D),"") | G55: =IFERROR(COUNTIF('נתוני אימונים'!B:B,"אירובי")/COUNTA('נתוני אימונים'!A3:A999),"")
...

Sheet גרפים
A1: חודש | B1: מהירות | C1: דופק | D1: DPS | E1: יעילות
A2: דצמבר 2025 | B2: =IFERROR(AVERAGEIFS('נתוני אימונים'!F:F,'נתוני אימונים'!A:A,"*.12.2025*"),0) | C2: =IFERROR(AVERAGEIFS('נתוני אימונים'!G:G,'נתוני אימונים'!A:A,"*.12.2025*"),0) | D2: =IFERROR(AVERAGEIFS('נתוני אימונים'!I:I,'נתוני אימונים'!A:A,"*.12.2025*"),0) | E2: =IFERROR(B2/C2,0)
A3: ינואר 2026 | B3: =IFERROR(AVERAGEIFS('נתוני אימונים'!F:F,'נתוני אימונים'!A:A,"*.01.2026*"),0) | C3: =IFERROR(AVERAGEIFS('נתוני אימונים'!G:G,'נתוני אימונים'!A:A,"*.01.2026*"),0) | D3: =IFERROR(AVERAGEIFS('נתוני אימונים'!I:I,'נתוני אימונים'!A:A,"*.01.2026*"),0) | E3: =IFERROR(B3/C3,0)
A4: פברואר 2026 | B4: =IFERROR(AVERAGEIFS('נתוני אימונים'!F:F,'נתוני אימונים'!A:A,"*.02.2026*"),0) | C4: =IFERROR(AVERAGEIFS('נתוני אימונים'!G:G,'נתוני אימונים'!A:A,"*.02.2026*"),0) | D4: =IFERROR(AVERAGEIFS('נתוני אימונים'!I:I,'נתוני אימונים'!A:A,"*.02.2026*"),0) | E4: =IFERROR(B4/C4,0)
A5: מרץ 2026 | B5: =IFERROR(AVERAGEIFS('נתוני אימונים'!F:F,'נתוני אימונים'!A:A,"*.03.2026*"),0) | C5: =IFERROR(AVERAGEIFS('נתוני אימונים'!G:G,'נתוני אימונים'!A:A,"*.03.2026*"),0) | D5: =IFERROR(AVERAGEIFS('נתוני אימונים'!I:I,'נתוני אימונים'!A:A,"*.03.2026*"),0) | E5: =IFERROR(B5/C5,0)
A6: אפריל 2026 | B6: =IFERROR(AVERAGEIFS('נתוני אימונים'!F:F,'נתוני אימונים'!A:A,"*.04.2026*"),0) | C6: =IFERROR(AVERAGEIFS('נתוני אימונים'!G:G,'נתוני אימונים'!A:A,"*.04.2026*"),0) | D6: =IFERROR(AVERAGEIFS('נתוני אימונים'!I:I,'נתוני אימונים'!A:A,"*.04.2026*"),0) | E6: =IFERROR(B6/C6,0)
A7: מאי 2026 | B7: =IFERROR(AVERAGEIFS('נתוני אימונים'!F:F,'נתוני אימונים'!A:A,"*.05.2026*"),0) | C7: =IFERROR(AVERAGEIFS('נתוני אימונים'!G:G,'נתוני אימונים'!A:A,"*.05.2026*"),0) | D7: =IFERROR(AVERAGEIFS('נתוני אימונים'!I:I,'נתוני אימונים'!A:A,"*.05.2026*"),0) | E7: =IFERROR(B7/C7,0)
A8: יוני 2026 | B8: =IFERROR(AVERAGEIFS('נתוני אימונים'!F:F,'נתוני אימונים'!A:A,"*.06.2026*"),0) | C8: =IFERROR(AVERAGEIFS('נתוני אימונים'!G:G,'נתוני אימונים'!A:A,"*.06.2026*"),0) | D8: =IFERROR(AVERAGEIFS('נתוני אימונים'!I:I,'נתוני אימונים'!A:A,"*.06.2026*"),0) | E8: =IFERROR(B8/C8,0)
